<?xml version="1.0"?>
<robot xmlns:xacro="http://www.ros.org/wiki/xacro" name="mp_500">

  <xacro:macro name="fixed_wheel_right" params="name parent number *origin">
    <joint name="${name}_joint" type="revolute">
    <xacro:insert_block name="origin" />
    <limit effort="1000.0" lower="-1e+16" upper="1e+16" velocity="3.5"/>
    <axis xyz="-1 0 0" />
    <joint_properties damping="0" friction="0.0" />
    <parent link="base_link" />
    <child link="${name}_link" />
   </joint>

   <transmission name="tran_${number}">
    <type>transmission_interface/SimpleTransmission</type>
    <joint name="${name}_joint" type="revolute">
      <hardwareInterface>hardware_interface/VelocityJointInterface</hardwareInterface>
        </joint>

      <actuator name="right_wheel_actuator">
      <mechanicalReduction>7</mechanicalReduction>
            <hardwareInterface>hardware_interface/VelocityJointInterface</hardwareInterface>

      </actuator>
  </transmission>



   <link name="${name}_link" type="wheel">
    <inertial>
      <origin xyz="0 0 0" rpy="0 0 0"/>
        <mass value="1.82362"/>
        <inertia ixx="0.00399743171" ixy="0.00000004464" ixz="-0.00000002245"
                 iyy="0.00399741733" iyz="-0.00000000164"
                 izz="0.00739239692"/>
</inertial>
    <visual>
    <origin xyz="0 0 0" rpy="0 0 0" />
        <geometry>
            <mesh filename="package://neo_simulation/robots/mp_500/meshes/MP-500-WHEEL-RIGHT.dae" scale="0.001 0.001 0.001"/>
        </geometry>
      </visual>

    <collision>
     <origin xyz="0 0 0" rpy="0 0 0" />
      <geometry>
            <mesh filename="package://neo_simulation/robots/mp_500/meshes/MP-500-WHEEL-RIGHT.dae" scale="0.001 0.001 0.001"/>
      </geometry>
    </collision>
</link>

  <gazebo reference="${name}_link">
      <mu1 value = "300.0"/>
      <mu2 value = "100.0"/>
      <kp value="8000.0" />
      <kd value="1460.0" />
      <fdir1 value="0.5 0 0"/>
</gazebo>
   
  </xacro:macro>
  
</robot>


