<?xml version="1.0" ?>
<!-- =================================================================================== -->
<!-- |    This document was autogenerated by xacro from mp_500.urdf.xacro              | -->
<!-- |    EDITING THIS FILE BY HAND IS NOT RECOMMENDED                                 | -->
<!-- =================================================================================== -->
<robot name="mp_500">
  <gazebo>
    <plugin filename="libgazebo_ros_diff_drive.so" name="differential_drive_controller">
      <alwaysOn>true</alwaysOn>
      <updateRate>40</updateRate>
      <legacyMode>false</legacyMode>
      <leftJoint>wheel_left_joint</leftJoint>
      <rightJoint>wheel_right_joint</rightJoint>
      <wheelSeparation>0.592</wheelSeparation>
      <wheelDiameter>0.260</wheelDiameter>
      <torque>20</torque>
      <commandTopic>cmd_vel</commandTopic>
      <odometryTopic>odom</odometryTopic>
      <odometryFrame>odom</odometryFrame>
      <robotBaseFrame>base_link</robotBaseFrame>
      <publishWheelTF>false</publishWheelTF>
      <publishWheelJointState>true</publishWheelJointState>
      <rosDebugLevel>na</rosDebugLevel>
      <wheelAcceleration>0</wheelAcceleration>
      <wheelTorque>5</wheelTorque>
      <odometrySource>world</odometrySource>
      <publishTf>true</publishTf>
      <publishOdomTF>true</publishOdomTF>
    </plugin>
  </gazebo>
  <gazebo reference="lidar_1_link">
    <sensor name="lidar_1_link" type="ray">
      <pose>0 0 0 0 0 0</pose>
      <visualize>false</visualize>
      <update_rate>100</update_rate>
      <ray>
        <scan>
          <horizontal>
            <samples>720</samples>
            <resolution>1</resolution>
            <min_angle>-1.48353</min_angle>
            <max_angle>1.48353</max_angle>
          </horizontal>
        </scan>
        <range>
          <min>0.10</min>
          <max>30.0</max>
          <resolution>0.05</resolution>
        </range>
        <noise>
          <type>gaussian</type>
          <!-- Noise parameters based on published spec for Hokuyo laser
                   achieving "+-30mm" accuracy at range < 10m.  A mean of 0.0m and
                   stddev of 0.01m will put 99.7% of samples within 0.03m of the true
                   reading. -->
          <mean>0.0</mean>
          <stddev>0.01</stddev>
        </noise>
      </ray>
      <plugin filename="libgazebo_ros_laser.so" name="lidar_1_link">
        <topicName>lidar_1/scan_filtered</topicName>
        <frameName>lidar_1_link</frameName>
      </plugin>
    </sensor>
  </gazebo>
  <!-- IMU sensor -->
  <gazebo reference="imu_link">
    <gravity>true</gravity>
    <sensor name="imu_sensor" type="imu">
      <always_on>true</always_on>
      <update_rate>100</update_rate>
      <visualize>true</visualize>
      <topic>__default_topic__</topic>
      <plugin filename="libgazebo_ros_imu_sensor.so" name="imu_plugin">
        <topicName>imu</topicName>
        <bodyName>imu_link</bodyName>
        <updateRateHZ>10.0</updateRateHZ>
        <gaussianNoise>0.0</gaussianNoise>
        <xyzOffset>0 0 0</xyzOffset>
        <rpyOffset>0 0 0</rpyOffset>
        <frameName>imu_link</frameName>
      </plugin>
      <pose>0 0 0 0 0 0</pose>
    </sensor>
  </gazebo>
  <!-- Ultrasonic sensors -->
  <gazebo reference="us_1_link">
    <!-- Visuals / Collisions omitted for this example -->
    <sensor name="range" type="ray">
      <ray>
        <scan>
          <horizontal>
            <samples>1</samples>
            <resolution>1.0</resolution>
            <min_angle>-0.01</min_angle>
            <max_angle>0.01</max_angle>
          </horizontal>
          <vertical>
            <samples>1</samples>
            <resolution>1</resolution>
            <min_angle>-0.01</min_angle>
            <max_angle>0.01</max_angle>
          </vertical>
        </scan>
        <range>
          <min>0.01</min>
          <max>3.75</max>
          <resolution>0.02</resolution>
        </range>
      </ray>
      <plugin filename="libgazebo_ros_range.so" name="libgazebo_ros_range">
        <gaussianNoise>0.005</gaussianNoise>
        <alwaysOn>true</alwaysOn>
        <updateRate>50</updateRate>
        <topicName>ultrasonic/us1</topicName>
        <frameName>us_1_link</frameName>
        <radiation>SONAR</radiation>
        <fov>0.2967</fov>
      </plugin>
    </sensor>
  </gazebo>
  <!-- camera -->
  <gazebo reference="camera_link">
    <sensor name="camera1" type="camera">
      <update_rate>30.0</update_rate>
      <camera name="head">
        <horizontal_fov>1.3962634</horizontal_fov>
        <image>
          <width>800</width>
          <height>800</height>
          <format>R8G8B8</format>
        </image>
        <clip>
          <near>0.02</near>
          <far>300</far>
        </clip>
        <noise>
          <type>gaussian</type>
          <!-- Noise is sampled independently per pixel on each frame.
               That pixel's noise value is added to each of its color
               channels, which at that point lie in the range [0,1]. -->
          <mean>0.0</mean>
          <stddev>0.007</stddev>
        </noise>
      </camera>
      <plugin filename="libgazebo_ros_camera.so" name="camera_controller">
        <alwaysOn>true</alwaysOn>
        <updateRate>0.0</updateRate>
        <cameraName>camera1</cameraName>
        <imageTopicName>image_raw</imageTopicName>
        <cameraInfoTopicName>camera_info</cameraInfoTopicName>
        <frameName>camera_link</frameName>
        <hackBaseline>0.07</hackBaseline>
        <distortionK1>0.0</distortionK1>
        <distortionK2>0.0</distortionK2>
        <distortionK3>0.0</distortionK3>
        <distortionT1>0.0</distortionT1>
        <distortionT2>0.0</distortionT2>
      </plugin>
    </sensor>
  </gazebo>
  <!-- <gazebo>
  <plugin name="gazebo_ros_control" filename="libgazebo_ros_control.so">
 <legacyModeNS> false </legacyModeNS> 
  <robotParam>/robot_description</robotParam>
       <robotSimType>gazebo_ros_control/DefaultRobotHWSim</robotSimType>
  </plugin>
</gazebo> -->
  <!--++++++++++++++++++++++++++++++base_link++++++++++++++++++++++++++++++++++++++++++++++++++++-->
  <!--++++++++++++++++++++body++++++++++++++++++++++++++++-->
  <!-- SENSORS -->
  <!-- Sick S300 - Comment/Uncomment if required  -->
  <!-- Microscan - Comment/Uncomment if required -->
  <!-- <xacro:include filename="$(find neo_simulation)/robots/mp_500/xacros/micro_scan.xacro" /> -->
  <!-- USS, IMU and Camera- Comment/Uncomment if required  -->
  <!-->
  <xacro:include filename="$(find neo_simulation)/robots/mp_500/xacros/imu.xacro" />
  <xacro:include filename="$(find neo_simulation)/robots/mp_500/xacros/ultrasonic.xacro" />
  <xacro:include filename="$(find neo_simulation)/robots/mp_500/xacros/camera.xacro" />
  <-->
  <link name="base_link"/>
  <joint name="base_footprint_joint" type="fixed">
    <origin rpy="0 0 0" xyz="0 0 0"/>
    <axis xyz="0 0 -1"/>
    <!-- <limit effort="1000.0" lower="-1e+16" upper="1e+16" velocity="3.5"/> -->
    <joint_properties damping="1" friction="1"/>
    <parent link="base_link"/>
    <child link="base_footprint"/>
  </joint>
  <link name="base_footprint">
    <inertial>
      <mass value="5"/>
      <origin rpy="0 0 0" xyz="0 0 0"/>
      <inertia ixx="1.71402" ixy="0.0" ixz="0.0" iyy="0.8856" iyz="0.0" izz="2.5725"/>
    </inertial>
    <visual name="body">
      <origin rpy="0 0 1.570796" xyz="0.0 0.0 0"/>
      <geometry>
        <mesh filename="package://neo_simulation/robots/mp_500/meshes/MP-500-BODY.dae" scale="0.001 0.001 0.001"/>
      </geometry>
    </visual>
    <collision name="body_collision">
      <origin rpy=" 0 0. 1.570796" xyz="0.0 0.0 0.0"/>
      <geometry>
        <mesh filename="package://neo_simulation/robots/mp_500/meshes/MP-500-BODY.dae" scale="0.001 0.001 0.001"/>
      </geometry>
    </collision>
  </link>
  <joint name="caster_wheel_joint" type="fixed">
    <origin rpy="-1.570796 0 1.570796 " xyz="-0.43 0. 0.176"/>
    <axis xyz="0 -1 0"/>
    <limit effort="1000.0" lower="-1e+16" upper="1e+16" velocity="3.5"/>
    <parent link="base_footprint"/>
    <child link="caster_wheel_link"/>
    <joint_properties damping="1.0" friction="1.0"/>
  </joint>
  <link name="caster_wheel_link" type="wheel">
    <inertial>
      <mass value="1.82362"/>
      <inertia ixx="0.00499743171" ixy="0.00000004464" ixz="-0.00000002245" iyy="0.00499741733" iyz="0.00000000164" izz="0.00839239692"/>
    </inertial>
    <visual name="castor_wheel">
      <origin rpy="0 0 0" xyz="0 0 0"/>
      <geometry>
        <mesh filename="package://neo_simulation/robots/mp_500/meshes/MP-500-WHEEL.dae" scale="0.001 0.001 0.001"/>
      </geometry>
    </visual>
    <collision>
      <origin rpy="0 0 0" xyz="0 0 0"/>
      <geometry>
        <mesh filename="package://neo_simulation/robots/mp_500/meshes/MP-500-WHEEL.dae" scale="0.001 0.001 0.001"/>
      </geometry>
    </collision>
  </link>
  <gazebo reference="caster_wheel_link">
    <kp>8000.0</kp>
    <kd>1460.0</kd>
    <mu1>0.5</mu1>
    <mu2>0.2</mu2>
    <fdir1>1 0 0</fdir1>
    <maxVel>3.0</maxVel>
    <minDepth>0.00</minDepth>
  </gazebo>
  <joint name="wheel_right_joint" type="revolute">
    <origin rpy="0 0 -1.570796" xyz="0. -0.25 0.13"/>
    <limit effort="1000.0" lower="-1e+16" upper="1e+16" velocity="3.5"/>
    <axis xyz="-1 0 0"/>
    <joint_properties damping="0" friction="0.0"/>
    <parent link="base_link"/>
    <child link="wheel_right_link"/>
  </joint>
  <link name="wheel_right_link" type="wheel">
    <inertial>
      <origin rpy="0 0 0" xyz="0 0 0"/>
      <mass value="1.82362"/>
      <inertia ixx="0.00399743171" ixy="0.00000004464" ixz="-0.00000002245" iyy="0.00399741733" iyz="-0.00000000164" izz="0.00739239692"/>
    </inertial>
    <visual>
      <origin rpy="0 0 0" xyz="0 0 0"/>
      <geometry>
        <mesh filename="package://neo_simulation/robots/mp_500/meshes/MP-500-WHEEL-RIGHT.dae" scale="0.001 0.001 0.001"/>
      </geometry>
    </visual>
    <collision>
      <origin rpy="0 0 0" xyz="0 0 0"/>
      <geometry>
        <mesh filename="package://neo_simulation/robots/mp_500/meshes/MP-500-WHEEL-RIGHT.dae" scale="0.001 0.001 0.001"/>
      </geometry>
    </collision>
  </link>
  <joint name="wheel_left_joint" type="revolute">
    <origin rpy="0 0 -1.570796" xyz="0. 0.25 0.13"/>
    <limit effort="1000.0" lower="-1e+16" upper="1e+16" velocity="3.5"/>
    <axis xyz="-1 0 0"/>
    <joint_properties damping="0" friction="0.0"/>
    <parent link="base_link"/>
    <child link="wheel_left_link"/>
  </joint>
  <link name="wheel_left_link" type="wheel">
    <inertial>
      <origin rpy="0 0 0" xyz="0 0 0"/>
      <mass value="1.82362"/>
      <inertia ixx="0.00399743171" ixy="0.00000004464" ixz="-0.00000002245" iyy="0.00399741733" iyz="-0.00000000164" izz="0.00739239692"/>
    </inertial>
    <visual>
      <origin rpy="0 0 3.14" xyz="0 0 0"/>
      <geometry>
        <mesh filename="package://neo_simulation/robots/mp_500/meshes/MP-500-WHEEL-LEFT.dae" scale="0.001 0.001 0.001"/>
      </geometry>
    </visual>
    <collision>
      <origin rpy="0 0 0" xyz="0 0 0"/>
      <geometry>
        <mesh filename="package://neo_simulation/robots/mp_500/meshes/MP-500-WHEEL-LEFT.dae" scale="0.001 0.001 0.001"/>
      </geometry>
    </collision>
  </link>
  <joint name="lidar_1_joint" type="fixed">
    <axis xyz="0 1 0"/>
    <origin rpy="3.14 0 0" xyz="0.244 0 0.141"/>
    <parent link="base_link"/>
    <child link="lidar_1_link"/>
  </joint>
  <link name="lidar_1_link" type="laser">
    <inertial>
      <mass value="0.001"/>
      <origin rpy="0 0 0" xyz="0 0 0"/>
      <inertia ixx="0.0001" ixy="0" ixz="0" iyy="0.000001" iyz="0" izz="0.0001"/>
    </inertial>
    <visual>
      <origin rpy="-1.57 0 3.14" xyz="0 0 -0.12"/>
      <geometry>
        <mesh filename="package://neo_simulation/robots/mp_500/meshes/SICK-S300.dae" scale="0.001 0.001 0.001"/>
      </geometry>
    </visual>
    <collision>
      <origin rpy="-1.57 0 3.14" xyz="0 0 -0.12"/>
      <geometry>
        <mesh filename="package://neo_simulation/robots/mp_500/meshes/SICK-S300.dae" scale="0.001 0.001 0.001"/>
      </geometry>
    </collision>
  </link>
  <!--+++++++++++++++++++ IMU ++++++++++++++++++++++++-->
  <!-- Comment or uncomment based on your requirement -->
  <!--><xacro:imu name="imu" parent="base_link">
    <origin xyz="0.100 0 0.300" rpy="0 0 3.14" />
  </xacro:imu><-->
  <!--+++++++++++++++++++ Ultra Sonic ++++++++++++++++++++++++-->
  <!-- Comment or uncomment based on your requirement -->
  <!-- SENSOR 1 -->
  <!--><xacro:us_sensor name="us_1" parent="base_link">
    <origin xyz="0.100 0 0.500" rpy="0 3.14 3.14" />
  </xacro:us_sensor><-->
  <!-- SENSOR 2 -->
  <!-- xacro:us_sensor name="us_2" parent="base_link">
    <origin xyz="0.110 0 0.300" rpy="0 3.14 3.14" />
  </xacro:us_sensor-->
  <!-- SENSOR 3 -->
  <!-- xacro:us_sensor name="us_3" parent="base_link">
    <origin xyz="0.120 0 0.300" rpy="0 3.14 3.14" />
  </xacro:us_sensor-->
  <!-- SENSOR 4 -->
  <!-- xacro:us_sensor name="us_4" parent="base_link">
    <origin xyz="0.130 0 0.300" rpy="0 3.14 3.14" />
  </xacro:us_sensor-->
  <!-- SENSOR 5 -->
  <!-- xacro:us_sensor name="us_5" parent="base_link">
    <origin xyz="0.140 0 0.300" rpy="0 3.14 3.14" />
  </xacro:us_sensor-->
  <!-- SENSOR 6 -->
  <!-- xacro:us_sensor name="us_6" parent="base_link">
    <origin xyz="0.150 0 0.300" rpy="0 3.14 3.14" />
  </xacro:us_sensor-->
  <!-- SENSOR 7 -->
  <!-- xacro:us_sensor name="us_7" parent="base_link">
    <origin xyz="0.160 0 0.300" rpy="0 3.14 3.14" />
  </xacro:us_sensor-->
  <!-- SENSOR 8 -->
  <!-- xacro:us_sensor name="us_8" parent="base_link">
    <origin xyz="0.170 0 0.300" rpy="0 3.14 3.14" />
  </xacro:us_sensor-->
  <!-- SENSOR 9 -->
  <!-- xacro:us_sensor name="us_9" parent="base_link">
    <origin xyz="0.180 0 0.300" rpy="0 3.14 3.14" />
  </xacro:us_sensor-->
  <!-- SENSOR 10 -->
  <!-- xacro:us_sensor name="us_10" parent="base_link">
    <origin xyz="0.100 0 0.300" rpy="0 3.14 3.14" />
  </xacro:us_sensor-->
  <!-- SENSOR 11 -->
  <!-- xacro:us_sensor name="us_11" parent="base_link">
    <origin xyz="0.100 0 0.300" rpy="0 3.14 3.14" />
  </xacro:us_sensor-->
  <!-- SENSOR 12 -->
  <!-- xacro:us_sensor name="us_12" parent="base_link">
    <origin xyz="0.190 0 0.300" rpy="0 3.14 3.14" />
  </xacro:us_sensor-->
  <!-- SENSOR 13 -->
  <!-- xacro:us_sensor name="us_13" parent="base_link">
    <origin xyz="0.200 0 0.300" rpy="0 3.14 3.14" />
  </xacro:us_sensor-->
  <!-- SENSOR 14 -->
  <!-- xacro:us_sensor name="us_14" parent="base_link">
    <origin xyz="0.210 0 0.300" rpy="0 3.14 3.14" />
  </xacro:us_sensor-->
  <!-- SENSOR 15 -->
  <!-- xacro:us_sensor name="us_15" parent="base_link">
    <origin xyz="0.220 0 0.300" rpy="0 3.14 3.14" />
  </xacro:us_sensor-->
  <!-- SENSOR 16 -->
  <!-- xacro:us_sensor name="us_16" parent="base_link">
    <origin xyz="0.230 0 0.300" rpy="0 3.14 3.14" />
  </xacro:us_sensor-->
  <!--Camera  -->
  <!-- <xacro:camera name="camera" parent="base_link">
    <origin xyz="0 0 0.38" rpy="0 0 0" />
  </xacro:camera>
 -->
</robot>

