<?xml version="1.0" ?>
<!-- =================================================================================== -->
<!-- |    This document was autogenerated by xacro from mmo_500.urdf.xacro             | -->
<!-- |    EDITING THIS FILE BY HAND IS NOT RECOMMENDED                                 | -->
<!-- =================================================================================== -->
<robot name="mmo_500" xmlns:xacro="http://ros.org/wiki/xacro">
  <!--GAZEBO REFERENCES 
  MPO_500-->
  <gazebo reference="base_link">
    <gravity>true</gravity>
    <self_collide>false</self_collide>
    <material value="Gazebo/Grey"/>
  </gazebo>
  <gazebo reference="wheel_front_left_link">
    <gravity>true</gravity>
    <self_collide>false</self_collide>
    <material value="Gazebo/Black"/>
  </gazebo>
  <gazebo reference="wheel_front_right_link">
    <gravity>true</gravity>
    <self_collide>false</self_collide>
    <material value="Gazebo/Black"/>
  </gazebo>
  <gazebo reference="wheel_back_left_link">
    <gravity>true</gravity>
    <self_collide>false</self_collide>
    <material value="Gazebo/Black"/>
  </gazebo>
  <gazebo reference="wheel_back_right_link">
    <gravity>true</gravity>
    <self_collide>false</self_collide>
    <material value="Gazebo/Black"/>
  </gazebo>
  <gazebo reference="sick_s300_laser_front_link">
    <material value="Gazebo/Yellow"/>
    <sensor name="sick_s300_laser_front_sensor" type="ray">
      <pose>0 0 0 0 0 0</pose>
      <visualize>true</visualize>
      <update_rate>40</update_rate>
      <ray>
        <scan>
          <horizontal>
            <samples>720</samples>
            <resolution>1</resolution>
            <min_angle>-1.91</min_angle>
            <max_angle>1.91</max_angle>
          </horizontal>
        </scan>
        <range>
          <min>0.10</min>
          <max>30.0</max>
          <resolution>0.05</resolution>
        </range>
        <noise>
          <type>gaussian</type>
          <!-- Noise parameters based on published spec for Hokuyo laser
                   achieving "+-30mm" accuracy at range < 10m.  A mean of 0.0m and
                   stddev of 0.01m will put 99.7% of samples within 0.03m of the true
                   reading. -->
          <mean>0.0</mean>
          <stddev>0.01</stddev>
        </noise>
      </ray>
      <plugin filename="libgazebo_ros_laser.so" name="sick_s300_laser_front">
        <topicName>sick_s300_laser/front/scan</topicName>
        <frameName>sick_s300_laser_front_link</frameName>
      </plugin>
    </sensor>
  </gazebo>
  <gazebo reference="sick_s300_laser_back_link">
    <material value="Gazebo/Yellow"/>
    <sensor name="sick_s300_laser_back_sensor" type="ray">
      <pose>0 0 0 0 0 0</pose>
      <visualize>true</visualize>
      <update_rate>40</update_rate>
      <ray>
        <scan>
          <horizontal>
            <samples>720</samples>
            <resolution>1</resolution>
            <min_angle>-2.26</min_angle>
            <max_angle>2.26</max_angle>
          </horizontal>
        </scan>
        <range>
          <min>0.10</min>
          <max>30.0</max>
          <resolution>0.05</resolution>
        </range>
        <noise>
          <type>gaussian</type>
          <!-- Noise parameters based on published spec for Hokuyo laser
                   achieving "+-30mm" accuracy at range < 10m.  A mean of 0.0m and
                   stddev of 0.01m will put 99.7% of samples within 0.03m of the true
                   reading. -->
          <mean>0.0</mean>
          <stddev>0.01</stddev>
        </noise>
      </ray>
      <plugin filename="libgazebo_ros_laser.so" name="sick_s300_laser_back">
        <topicName>sick_s300_laser/back/scan</topicName>
        <frameName>sick_s300_laser_back_link</frameName>
      </plugin>
    </sensor>
  </gazebo>
  <gazebo>
    <plugin filename="libgazebo_ros_planar_move.so" name="mpo_500_controller">
      <commandTopic>cmd_vel</commandTopic>
      <leftFrontJoint>wheel_front_left_joint</leftFrontJoint>
      <rightFrontJoint>wheel_front_right_joint</rightFrontJoint>
      <leftRearJoint>wheel_back_left_joint</leftRearJoint>
      <rightRearJoint>wheel_back_right_joint</rightRearJoint>
      <odometryTopic>odom</odometryTopic>
      <odometryFrame>odom</odometryFrame>
      <odometryRate>20.0</odometryRate>
      <robotBaseFrame>base_link</robotBaseFrame>
    </plugin>
  </gazebo>
  <!--CABINET-->
  <gazebo reference="cabinet_link">
    <gravity>true</gravity>
    <self_collide>false</self_collide>
    <material value="Gazebo/Grey"/>
  </gazebo>
  <!--ur10 -->
  <gazebo>
    <plugin filename="libgazebo_ros_control.so" name="ros_control">
      <alwaysOn>true</alwaysOn>
      <updateRate>1000.0</updateRate>
    </plugin>
    <!--
    <plugin name="gazebo_ros_power_monitor_controller" filename="libgazebo_ros_power_monitor.so">
      <alwaysOn>true</alwaysOn>
      <updateRate>1.0</updateRate>
      <timeout>5</timeout>
      <powerStateTopic>power_state</powerStateTopic>
      <powerStateRate>10.0</powerStateRate>
      <fullChargeCapacity>87.78</fullChargeCapacity>     
      <dischargeRate>-474</dischargeRate>
      <chargeRate>525</chargeRate>
      <dischargeVoltage>15.52</dischargeVoltage>
      <chargeVoltage>16.41</chargeVoltage>
    </plugin>
-->
  </gazebo>
  <!-- MATERIALS -->
  <material name="Neobotix/Black">
    <color rgba="0.0 0.0 0.0 1.0"/>
  </material>
  <material name="Neobotix/Blue">
    <color rgba="0.0 0.0 0.8 1.0"/>
  </material>
  <material name="Neobotix/Green">
    <color rgba="0.0 0.8 0.0 1.0"/>
  </material>
  <material name="Neobotix/Grey">
    <color rgba="0.7 0.7 0.7 1.0"/>
  </material>
  <material name="Neobotix/Grey2">
    <color rgba="0.9 0.9 0.9 1.0"/>
  </material>
  <material name="Neobotix/Red">
    <color rgba="0.8 0.0 0.0 1.0"/>
  </material>
  <material name="Neobotix/White">
    <color rgba="1.0 1.0 1.0 1.0"/>
  </material>
  <material name="Neobotix/Yellow">
    <color rgba="1.0 1.0 0 10"/>
  </material>
  <!-- BODY -->
  <!-- WHEELS -->
  <!-- SENSORS -->
  <!-- CABINET -->
  <!--ur10 -->
  <!--
  Author: Kelsey Hawkins
  Contributers: Jimmy Da Silva, Ajit Krisshna N L, Muhammad Asif Rana-->
  <!-- Inertia parameters -->
  <!-- This mass might be incorrect -->
  <!-- These parameters are borrowed from the urcontrol.conf file
       but are not verified for the correct permutation.
       The permutation was guessed by looking at the UR5 parameters.
       Serious use of these parameters needs further inspection. -->
  <!-- Kinematic model -->
  <!-- Properties from urcontrol.conf -->
  <!-- Arbitrary offsets for shoulder/elbow joints -->
  <!-- measured from model -->
  <!-- measured from model -->
  <!-- link lengths used in model -->
  <!-- Base Macro-->
  <link name="base_link">
    <inertial>
      <mass value="50"/>
      <origin rpy="0 0 0" xyz="0 0 0"/>
      <inertia ixx="2.8567" ixy="0.0" ixz="0.0" iyy="1.476" iyz="0.0" izz="4.2875"/>
    </inertial>
    <visual>
      <origin rpy="0 0 1.571" xyz="0. 0. 0.215"/>
      <geometry>
        <mesh filename="package://neo_simulation/robots/mmo_500/meshes/mpo_500/MPO-500-BODY.STL"/>
      </geometry>
      <material name="Neobotix/Grey"/>
    </visual>
    <collision>
      <origin rpy="0 0 0" xyz="0. 0. 0.2"/>
      <geometry>
        <!--<box size="0.68 0.41 0.25"/> -->
        <box size="0.769 0.51 0.307"/>
      </geometry>
    </collision>
  </link>
  <!-- Wheel Macro -->
  <joint name="wheel_front_left_joint" type="continuous">
    <origin rpy="0 0 0" xyz="0.25 0.28 0.13"/>
    <axis xyz="0 1 0"/>
    <joint_properties damping="1" friction="1"/>
    <parent link="base_link"/>
    <child link="wheel_front_left_link"/>
  </joint>
  <link name="wheel_front_left_link" type="wheel">
    <inertial>
      <mass value="0.5"/>
      <origin rpy="0 0 0" xyz="0 0 0"/>
      <inertia ixx="0.0022166" ixy="0" ixz="0" iyy="0.0022166" iyz="0" izz="0.0036"/>
    </inertial>
    <visual>
      <origin rpy="0 0 1.571" xyz="0 0 0"/>
      <geometry>
        <mesh filename="package://neo_simulation/robots/mmo_500/meshes/mpo_500/Mecanum-Rad links.stl" scale="0.001 0.001 0.001"/>
      </geometry>
      <material name="Neobotix/Black"/>
    </visual>
    <collision>
      <origin rpy="1.59 0 0" xyz="0 0 0"/>
      <geometry>
        <cylinder length="0.1" radius="0.12"/>
      </geometry>
    </collision>
  </link>
  <joint name="wheel_front_right_joint" type="continuous">
    <origin rpy="0 0 0" xyz="0.25 -0.28 0.13"/>
    <axis xyz="0 1 0"/>
    <joint_properties damping="1" friction="1"/>
    <parent link="base_link"/>
    <child link="wheel_front_right_link"/>
  </joint>
  <link name="wheel_front_right_link" type="wheel">
    <inertial>
      <mass value="0.5"/>
      <origin rpy="0 0 0" xyz="0 0 0"/>
      <inertia ixx="0.0022166" ixy="0" ixz="0" iyy="0.0022166" iyz="0" izz="0.0036"/>
    </inertial>
    <visual>
      <origin rpy="0 0 1.571" xyz="0 0 0"/>
      <geometry>
        <mesh filename="package://neo_simulation/robots/mmo_500/meshes/mpo_500/Mecanum-Rad rechts.stl" scale="0.001 0.001 0.001"/>
      </geometry>
      <material name="Neobotix/Black"/>
    </visual>
    <collision>
      <origin rpy="1.59 0 0" xyz="0 0 0"/>
      <geometry>
        <cylinder length="0.1" radius="0.12"/>
      </geometry>
    </collision>
  </link>
  <joint name="wheel_back_left_joint" type="continuous">
    <origin rpy="0 0 0" xyz="-0.25 0.28 0.13"/>
    <axis xyz="0 1 0"/>
    <joint_properties damping="1" friction="1"/>
    <parent link="base_link"/>
    <child link="wheel_back_left_link"/>
  </joint>
  <link name="wheel_back_left_link" type="wheel">
    <inertial>
      <mass value="0.5"/>
      <origin rpy="0 0 0" xyz="0 0 0"/>
      <inertia ixx="0.0022166" ixy="0" ixz="0" iyy="0.0022166" iyz="0" izz="0.0036"/>
    </inertial>
    <visual>
      <origin rpy="0 0 1.571" xyz="0 0 0"/>
      <geometry>
        <mesh filename="package://neo_simulation/robots/mmo_500/meshes/mpo_500/Mecanum-Rad links.stl" scale="0.001 0.001 0.001"/>
      </geometry>
      <material name="Neobotix/Black"/>
    </visual>
    <collision>
      <origin rpy="1.59 0 0" xyz="0 0 0"/>
      <geometry>
        <cylinder length="0.1" radius="0.12"/>
      </geometry>
    </collision>
  </link>
  <joint name="wheel_back_right_joint" type="continuous">
    <origin rpy="0 0 0" xyz="-0.25 -0.28 0.13"/>
    <axis xyz="0 1 0"/>
    <joint_properties damping="1" friction="1"/>
    <parent link="base_link"/>
    <child link="wheel_back_right_link"/>
  </joint>
  <link name="wheel_back_right_link" type="wheel">
    <inertial>
      <mass value="0.5"/>
      <origin rpy="0 0 0" xyz="0 0 0"/>
      <inertia ixx="0.0022166" ixy="0" ixz="0" iyy="0.0022166" iyz="0" izz="0.0036"/>
    </inertial>
    <visual>
      <origin rpy="0 0 1.571" xyz="0 0 0"/>
      <geometry>
        <mesh filename="package://neo_simulation/robots/mmo_500/meshes/mpo_500/Mecanum-Rad rechts.stl" scale="0.001 0.001 0.001"/>
      </geometry>
      <material name="Neobotix/Black"/>
    </visual>
    <collision>
      <origin rpy="1.59 0 0" xyz="0 0 0"/>
      <geometry>
        <cylinder length="0.1" radius="0.12"/>
      </geometry>
    </collision>
  </link>
  <!-- Sensors -->
  <joint name="sick_s300_laser_front_joint" type="fixed">
    <axis xyz="0 1 0"/>
    <origin rpy="0 0 0" xyz="0.442 0 0.420"/>
    <parent link="base_link"/>
    <child link="sick_s300_laser_front_link"/>
  </joint>
  <link name="sick_s300_laser_front_link" type="laser">
    <inertial>
      <mass value="0.001"/>
      <origin rpy="0 0 0" xyz="0 0 0"/>
      <inertia ixx="0.0001" ixy="0" ixz="0" iyy="0.000001" iyz="0" izz="0.0001"/>
    </inertial>
    <visual>
      <origin rpy="0 0 -1.57" xyz="0 0 -0.04"/>
      <geometry>
        <mesh filename="package://neo_simulation/robots/mmo_500/meshes/mpo_500/MPO-500-SICK.STL"/>
      </geometry>
      <material name="Neobotix/Yellow"/>
    </visual>
    <collision>
      <origin rpy="0 0 0" xyz="0 0 0"/>
      <geometry>
        <cylinder length="0.154" radius="0.053"/>
      </geometry>
    </collision>
  </link>
  <joint name="sick_s300_laser_back_joint" type="fixed">
    <axis xyz="0 1 0"/>
    <origin rpy="0 0 3.14" xyz="-0.442 0 0.420"/>
    <parent link="base_link"/>
    <child link="sick_s300_laser_back_link"/>
  </joint>
  <link name="sick_s300_laser_back_link" type="laser">
    <inertial>
      <mass value="0.001"/>
      <origin rpy="0 0 0" xyz="0 0 0"/>
      <inertia ixx="0.0001" ixy="0" ixz="0" iyy="0.000001" iyz="0" izz="0.0001"/>
    </inertial>
    <visual>
      <origin rpy="0 0 -1.57" xyz="0 0 -0.04"/>
      <geometry>
        <mesh filename="package://neo_simulation/robots/mmo_500/meshes/mpo_500/MPO-500-SICK.STL"/>
      </geometry>
      <material name="Neobotix/Yellow"/>
    </visual>
    <collision>
      <origin rpy="0 0 0" xyz="0 0 0"/>
      <geometry>
        <cylinder length="0.154" radius="0.053"/>
      </geometry>
    </collision>
  </link>
  <!--cabinet-->
  <joint name="cabinet_joint" type="fixed">
    <origin rpy="0 0 0" xyz="0.072 0 0.386"/>
    <joint_properties damping="1" friction="1"/>
    <parent link="base_link"/>
    <child link="cabinet_link"/>
  </joint>
  <link name="cabinet_link">
    <inertial>
      <mass value="8"/>
      <origin rpy="0 0 0" xyz="0 0 0"/>
      <inertia ixx="0.457072" ixy="0.0" ixz="0.0" iyy="0.23616" iyz="0.0" izz="0.686"/>
    </inertial>
    <visual>
      <origin rpy="0 0 -1.5708" xyz="0 0 0"/>
      <geometry>
        <mesh filename="package://neo_simulation/robots/mmo_500/meshes/cabinet/MMO-500 V1.1 UR10 Schaltschrank2.stl" scale="0.001 0.001 0.001"/>
      </geometry>
      <material name="Neobotix/Grey"/>
    </visual>
    <collision>
      <origin rpy="0 0 0" xyz="0. 0. 0"/>
      <geometry>
        <box size="0.496 0.55 0.416"/>
      </geometry>
    </collision>
  </link>
  <!--ur10-->
  <joint name="cabinet_u10_joint" type="fixed">
    <parent link="cabinet_link"/>
    <child link="ur10base_link"/>
    <origin rpy="0.0 0.0 0.0" xyz="0.133 0.0 0.416"/>
  </joint>
  <link name="ur10base_link">
    <visual>
      <geometry>
        <mesh filename="package://neo_simulation/robots/mmo_500/meshes/ur10/visual/base.dae"/>
      </geometry>
      <material name="LightGrey">
        <color rgba="0.7 0.7 0.7 1.0"/>
      </material>
    </visual>
    <collision>
      <geometry>
        <mesh filename="package://neo_simulation/robots/mmo_500/meshes/ur10/collision/base.stl"/>
      </geometry>
    </collision>
    <inertial>
      <mass value="0.3333"/>
      <origin rpy="0 0 0" xyz="0.0 0.0 0.0"/>
      <inertia ixx="0.000508810021476" ixy="0.0" ixz="0.0" iyy="0.000508810021476" iyz="0.0" izz="0.00093740625"/>
    </inertial>
  </link>
  <joint name="ur10shoulder_pan_joint" type="revolute">
    <parent link="ur10base_link"/>
    <child link="ur10shoulder_link"/>
    <origin rpy="0.0 0.0 0.0" xyz="0.0 0.0 0.1273"/>
    <axis xyz="0 0 1"/>
    <limit effort="330.0" lower="-3.14159265359" upper="3.14159265359" velocity="2.16"/>
    <dynamics damping="0.0" friction="0.0"/>
  </joint>
  <link name="ur10shoulder_link">
    <visual>
      <geometry>
        <mesh filename="package://neo_simulation/robots/mmo_500/meshes/ur10/visual/shoulder.dae"/>
      </geometry>
      <material name="LightGrey">
        <color rgba="0.7 0.7 0.7 1.0"/>
      </material>
    </visual>
    <collision>
      <geometry>
        <mesh filename="package://neo_simulation/robots/mmo_500/meshes/ur10/collision/shoulder.stl"/>
      </geometry>
    </collision>
    <inertial>
      <mass value="0.64816"/>
      <origin rpy="0 0 0" xyz="0.0 0.0 0.0"/>
      <inertia ixx="0.0026228324042" ixy="0.0" ixz="0.0" iyy="0.0026228324042" iyz="0.0" izz="0.00182295"/>
    </inertial>
  </link>
  <joint name="ur10shoulder_lift_joint" type="revolute">
    <parent link="ur10shoulder_link"/>
    <child link="ur10upper_arm_link"/>
    <origin rpy="0.0 -1.25 0.0" xyz="0.0 0.220941 0.0"/>
    <axis xyz="0 1 0"/>
    <limit effort="330.0" lower="-3.14159265359" upper="3.14159265359" velocity="2.16"/>
    <dynamics damping="0.0" friction="0.0"/>
  </joint>
  <link name="ur10upper_arm_link">
    <visual>
      <geometry>
        <mesh filename="package://neo_simulation/robots/mmo_500/meshes/ur10/visual/upperarm.dae"/>
      </geometry>
      <material name="LightGrey">
        <color rgba="0.7 0.7 0.7 1.0"/>
      </material>
    </visual>
    <collision>
      <geometry>
        <mesh filename="package://neo_simulation/robots/mmo_500/meshes/ur10/collision/upperarm.stl"/>
      </geometry>
    </collision>
    <inertial>
      <mass value="1.0775"/>
      <origin rpy="0 0 0" xyz="0.0 0.0 0.306"/>
      <inertia ixx="0.0351461503165" ixy="0.0" ixz="0.0" iyy="0.0351461503165" iyz="0.0" izz="0.00303046875"/>
    </inertial>
  </link>
  <joint name="ur10elbow_joint" type="revolute">
    <parent link="ur10upper_arm_link"/>
    <child link="ur10forearm_link"/>
    <origin rpy="0.0 -1.95 0.0" xyz="0.0 -0.1719 0.612"/>
    <axis xyz="0 1 0"/>
    <limit effort="150.0" lower="-3.14159265359" upper="3.14159265359" velocity="3.15"/>
    <dynamics damping="0.0" friction="0.0"/>
  </joint>
  <link name="ur10forearm_link">
    <visual>
      <geometry>
        <mesh filename="package://neo_simulation/robots/mmo_500/meshes/ur10/visual/forearm.dae"/>
      </geometry>
      <material name="LightGrey">
        <color rgba="0.7 0.7 0.7 1.0"/>
      </material>
    </visual>
    <collision>
      <geometry>
        <mesh filename="package://neo_simulation/robots/mmo_500/meshes/ur10/collision/forearm.stl"/>
      </geometry>
    </collision>
    <inertial>
      <mass value="0.43"/>
      <origin rpy="0 0 0" xyz="0.0 0.0 0.28615"/>
      <inertia ixx="0.0123410771219" ixy="0.0" ixz="0.0" iyy="0.0123410771219" iyz="0.0" izz="0.001209375"/>
    </inertial>
  </link>
  <joint name="ur10wrist_1_joint" type="revolute">
    <parent link="ur10forearm_link"/>
    <child link="ur10wrist_1_link"/>
    <origin rpy="0.0 1.57079632679 0.0" xyz="0.0 0.0 0.5723"/>
    <axis xyz="0 1 0"/>
    <limit effort="54.0" lower="-3.14159265359" upper="3.14159265359" velocity="3.2"/>
    <dynamics damping="0.0" friction="0.0"/>
  </joint>
  <link name="ur10wrist_1_link">
    <visual>
      <geometry>
        <mesh filename="package://neo_simulation/robots/mmo_500/meshes/ur10/visual/wrist1.dae"/>
      </geometry>
      <material name="LightGrey">
        <color rgba="0.7 0.7 0.7 1.0"/>
      </material>
    </visual>
    <collision>
      <geometry>
        <mesh filename="package://neo_simulation/robots/mmo_500/meshes/ur10/collision/wrist1.stl"/>
      </geometry>
    </collision>
    <inertial>
      <mass value="0.1633"/>
      <origin rpy="0 0 0" xyz="0.0 0.0 0.0"/>
      <inertia ixx="0.00042560045476" ixy="0.0" ixz="0.0" iyy="0.00042560045476" iyz="0.0" izz="0.00045928125"/>
    </inertial>
  </link>
  <joint name="ur10wrist_2_joint" type="revolute">
    <parent link="ur10wrist_1_link"/>
    <child link="ur10wrist_2_link"/>
    <origin rpy="0.0 0.0 0.0" xyz="0.0 0.1149 0.0"/>
    <axis xyz="0 0 1"/>
    <limit effort="54.0" lower="-3.14159265359" upper="3.14159265359" velocity="3.2"/>
    <dynamics damping="0.0" friction="0.0"/>
  </joint>
  <link name="ur10wrist_2_link">
    <visual>
      <geometry>
        <mesh filename="package://neo_simulation/robots/mmo_500/meshes/ur10/visual/wrist2.dae"/>
      </geometry>
      <material name="LightGrey">
        <color rgba="0.7 0.7 0.7 1.0"/>
      </material>
    </visual>
    <collision>
      <geometry>
        <mesh filename="package://neo_simulation/robots/mmo_500/meshes/ur10/collision/wrist2.stl"/>
      </geometry>
    </collision>
    <inertial>
      <mass value="0.1633"/>
      <origin rpy="0 0 0" xyz="0.0 0.0 0.0"/>
      <inertia ixx="0.00042560045476" ixy="0.0" ixz="0.0" iyy="0.00042560045476" iyz="0.0" izz="0.00045928125"/>
    </inertial>
  </link>
  <joint name="ur10wrist_3_joint" type="revolute">
    <parent link="ur10wrist_2_link"/>
    <child link="ur10wrist_3_link"/>
    <origin rpy="0.0 0.0 0.0" xyz="0.0 0.0 0.1157"/>
    <axis xyz="0 1 0"/>
    <limit effort="54.0" lower="-3.14159265359" upper="3.14159265359" velocity="3.2"/>
    <dynamics damping="0.0" friction="0.0"/>
  </joint>
  <link name="ur10wrist_3_link">
    <visual>
      <geometry>
        <mesh filename="package://neo_simulation/robots/mmo_500/meshes/ur10/visual/wrist3.dae"/>
      </geometry>
      <material name="LightGrey">
        <color rgba="0.7 0.7 0.7 1.0"/>
      </material>
    </visual>
    <collision>
      <geometry>
        <mesh filename="package://neo_simulation/robots/mmo_500/meshes/ur10/collision/wrist3.stl"/>
      </geometry>
    </collision>
    <inertial>
      <mass value="0.01683"/>
      <origin rpy="0 0 0" xyz="0.0 0.0 0.0"/>
      <inertia ixx="4.38631699547e-05" ixy="0.0" ixz="0.0" iyy="4.38631699547e-05" iyz="0.0" izz="4.7334375e-05"/>
    </inertial>
  </link>
  <joint name="ur10ee_fixed_joint" type="fixed">
    <parent link="ur10wrist_3_link"/>
    <child link="ur10ee_link"/>
    <origin rpy="0.0 0.0 1.57079632679" xyz="0.0 0.0922 0.0"/>
  </joint>
  <link name="ur10ee_link">
    <collision>
      <geometry>
        <box size="0.01 0.01 0.01"/>
      </geometry>
      <origin rpy="0 0 0" xyz="-0.01 0 0"/>
    </collision>
  </link>
  <transmission name="ur10shoulder_pan_trans">
    <type>transmission_interface/SimpleTransmission</type>
    <joint name="ur10shoulder_pan_joint">
      <hardwareInterface>PositionJointInterface</hardwareInterface>
    </joint>
    <actuator name="ur10shoulder_pan_motor">
      <hardwareInterface>PositionJointInterface</hardwareInterface>
      <mechanicalReduction>1</mechanicalReduction>
    </actuator>
  </transmission>
  <transmission name="ur10shoulder_lift_trans">
    <type>transmission_interface/SimpleTransmission</type>
    <joint name="ur10shoulder_lift_joint">
      <hardwareInterface>PositionJointInterface</hardwareInterface>
    </joint>
    <actuator name="ur10shoulder_lift_motor">
      <hardwareInterface>PositionJointInterface</hardwareInterface>
      <mechanicalReduction>1</mechanicalReduction>
    </actuator>
  </transmission>
  <transmission name="ur10elbow_trans">
    <type>transmission_interface/SimpleTransmission</type>
    <joint name="ur10elbow_joint">
      <hardwareInterface>PositionJointInterface</hardwareInterface>
    </joint>
    <actuator name="ur10elbow_motor">
      <hardwareInterface>PositionJointInterface</hardwareInterface>
      <mechanicalReduction>1</mechanicalReduction>
    </actuator>
  </transmission>
  <transmission name="ur10wrist_1_trans">
    <type>transmission_interface/SimpleTransmission</type>
    <joint name="ur10wrist_1_joint">
      <hardwareInterface>PositionJointInterface</hardwareInterface>
    </joint>
    <actuator name="ur10wrist_1_motor">
      <hardwareInterface>PositionJointInterface</hardwareInterface>
      <mechanicalReduction>1</mechanicalReduction>
    </actuator>
  </transmission>
  <transmission name="ur10wrist_2_trans">
    <type>transmission_interface/SimpleTransmission</type>
    <joint name="ur10wrist_2_joint">
      <hardwareInterface>PositionJointInterface</hardwareInterface>
    </joint>
    <actuator name="ur10wrist_2_motor">
      <hardwareInterface>PositionJointInterface</hardwareInterface>
      <mechanicalReduction>1</mechanicalReduction>
    </actuator>
  </transmission>
  <transmission name="ur10wrist_3_trans">
    <type>transmission_interface/SimpleTransmission</type>
    <joint name="ur10wrist_3_joint">
      <hardwareInterface>PositionJointInterface</hardwareInterface>
    </joint>
    <actuator name="ur10wrist_3_motor">
      <hardwareInterface>PositionJointInterface</hardwareInterface>
      <mechanicalReduction>1</mechanicalReduction>
    </actuator>
  </transmission>
  <gazebo reference="ur10base_link">
    <gravity>true</gravity>
    <self_collide>false</self_collide>
    <material value="Gazebo/Black"/>
  </gazebo>
  <gazebo reference="ur10forearm_link">
    <gravity>true</gravity>
    <self_collide>false</self_collide>
    <material value="Gazebo/Grey"/>
  </gazebo>
  <gazebo reference="ur10shoulder_link">
    <gravity>true</gravity>
    <self_collide>false</self_collide>
    <material value="Gazebo/Black"/>
  </gazebo>
  <gazebo reference="ur10upper_arm_link">
    <gravity>true</gravity>
    <self_collide>false</self_collide>
    <material value="Gazebo/Grey"/>
  </gazebo>
  <gazebo reference="ur10wrist_1_link">
    <gravity>true</gravity>
    <self_collide>false</self_collide>
    <material value="Gazebo/Black"/>
  </gazebo>
  <gazebo reference="ur10wrist_2_link">
    <gravity>true</gravity>
    <self_collide>false</self_collide>
    <material value="Gazebo/Grey"/>
  </gazebo>
  <gazebo reference="ur10wrist_3_link">
    <gravity>true</gravity>
    <self_collide>false</self_collide>
    <material value="Gazebo/Black"/>
  </gazebo>
  <!-- ROS base_link to UR 'Base' Coordinates transform
    <link name="${prefix}base"/>
    <joint name="${prefix}base_link-base_fixed_joint" type="fixed"-->
  &gt;
    
  <!--NOTE: this rotation is only needed as long as base_link itself is
                 not corrected wrt the real robot (ie: rotated over 180
                 degrees)
     
      <origin xyz="0 0 0" rpy="0 0 ${-pi}"/>
      <parent link="${prefix}base_link"/>
      <child link="${prefix}base"/>
    </joint>-->
  <!--Frame coincident with all-zeros TCP on UR controller
    <link name="${prefix}tool0"/>
    <joint name="${prefix}wrist_3_link-tool0_fixed_joint" type="fixed">
      <origin xyz="0 ${wrist_3_length} 0" rpy="${pi/-2.0} 0 0"/>
      <parent link="${prefix}wrist_3_link"/>
      <child link="${prefix}tool0"/>
    </joint> -->
</robot>
