<?xml version="1.0"?>
<robot xmlns:xacro="http://www.ros.org/wiki/xacro" name="mpo_700">

  <xacro:macro name="mpo_700_wheel" params="name parent *origin">
   <joint name="${name}_joint" type="revolute">
    <xacro:insert_block name="origin" />
    <limit effort="1000.0" lower="-1e+16" upper="1e+16" velocity="20.5"/>
    <axis xyz="0 -1 0" />
    <joint_properties damping="30" friction="110"/>
    <parent link="${parent}" />
    <child link="${name}_link" />
   </joint>

   <link name="${name}_link" type="wheel">
    <inertial>
      <mass value="1.2"/>
      <origin rpy="0 0 0" xyz="0 0 0"/>
      <inertia ixx="0.11042056" ixy="0.0" ixz="0.0" 
               iyy="0.11042056" iyz="0.0" 
               izz="0.11042056"/>
    </inertial>

    <visual>
     <origin xyz="0 0 0" rpy="0 0 3.14"/>
     <geometry>
        <mesh filename="package://neo_simulation/robots/mpo_700/meshes/MPO-700-WHEEL.dae" scale="0.001 0.001 0.001"/>
     </geometry>
    </visual>

    <collision>
     <origin xyz="0 0 0" rpy="0 0 0" />
     <geometry>
      <sphere radius="0.09" />
        <!-- <mesh filename="package://neo_simulation/robots/mpo_700/meshes/MPO-700-WHEEL.dae" scale="0.001 0.001 0.001"/> -->
     </geometry>
    </collision>
   </link>
   
  </xacro:macro>
  
</robot>


